<bound method Response.json of <Response [200]>>
Traceback (most recent call last):
  File "/usr/lib/python3/dist-packages/urllib3/connection.py", line 169, in _new_conn
  File "/usr/lib/python3/dist-packages/urllib3/util/connection.py", line 73, in create_connection
  File "/usr/lib/python3.10/socket.py", line 955, in getaddrinfo
OSError: [Errno 16] Device or resource busy

During handling of the above exception, another exception occurred:

Traceback (most recent call last):
  File "/usr/lib/python3/dist-packages/urllib3/connectionpool.py", line 699, in urlopen
  File "/usr/lib/python3/dist-packages/urllib3/connectionpool.py", line 394, in _make_request
  File "/usr/lib/python3/dist-packages/urllib3/connection.py", line 234, in request
  File "/usr/lib/python3.10/http/client.py", line 1282, in request
  File "/usr/lib/python3.10/http/client.py", line 1328, in _send_request
  File "/usr/lib/python3.10/http/client.py", line 1277, in endheaders
  File "/usr/lib/python3.10/http/client.py", line 1037, in _send_output
  File "/usr/lib/python3.10/http/client.py", line 975, in send
  File "/usr/lib/python3/dist-packages/urllib3/connection.py", line 200, in connect
  File "/usr/lib/python3/dist-packages/urllib3/connection.py", line 181, in _new_conn
urllib3.exceptions.NewConnectionError: <urllib3.connection.HTTPConnection object at 0xffff949f7cd0>: Failed to establish a new connection: [Errno 16] Device or resource busy

During handling of the above exception, another exception occurred:

Traceback (most recent call last):
  File "/usr/lib/python3/dist-packages/requests/adapters.py", line 439, in send
  File "/usr/lib/python3/dist-packages/urllib3/connectionpool.py", line 755, in urlopen
  File "/usr/lib/python3/dist-packages/urllib3/util/retry.py", line 574, in increment
urllib3.exceptions.MaxRetryError: HTTPConnectionPool(host='track.storm-chasers.cn', port=80): Max retries exceeded with url: /api/receive_meteo_data_json (Caused by NewConnectionError('<urllib3.connection.HTTPConnection object at 0xffff949f7cd0>: Failed to establish a new connection: [Errno 16] Device or resource busy'))

During handling of the above exception, another exception occurred:

Traceback (most recent call last):
  File "/home/tqm/post_sdk.py", line 42, in <module>
  File "/usr/lib/python3/dist-packages/requests/api.py", line 119, in post
  File "/usr/lib/python3/dist-packages/requests/api.py", line 61, in request
  File "/usr/lib/python3/dist-packages/requests/sessions.py", line 542, in request
  File "/usr/lib/python3/dist-packages/requests/sessions.py", line 655, in send
  File "/usr/lib/python3/dist-packages/requests/adapters.py", line 516, in send
requests.exceptions.ConnectionError: HTTPConnectionPool(host='track.storm-chasers.cn', port=80): Max retries exceeded with url: /api/receive_meteo_data_json (Caused by NewConnectionError('<urllib3.connection.HTTPConnection object at 0xffff949f7cd0>: Failed to establish a new connection: [Errno 16] Device or resource busy'))
